2020-02-05 11:09:34,454 INFO Website Starts up in [__init__.py 29]
2020-02-05 12:11:03,820 INFO Website Starts up in [__init__.py 29]
2020-02-05 12:11:07,271 ERROR Exception on /edit_profile [GET] in [app.py 1891]
Traceback (most recent call last):
  File "/Users/wujialiang/Public/website/venv/lib/python3.7/site-packages/flask/app.py", line 2446, in wsgi_app
    response = self.full_dispatch_request()
  File "/Users/wujialiang/Public/website/venv/lib/python3.7/site-packages/flask/app.py", line 1951, in full_dispatch_request
    rv = self.handle_user_exception(e)
  File "/Users/wujialiang/Public/website/venv/lib/python3.7/site-packages/flask/app.py", line 1820, in handle_user_exception
    reraise(exc_type, exc_value, tb)
  File "/Users/wujialiang/Public/website/venv/lib/python3.7/site-packages/flask/_compat.py", line 39, in reraise
    raise value
  File "/Users/wujialiang/Public/website/venv/lib/python3.7/site-packages/flask/app.py", line 1949, in full_dispatch_request
    rv = self.dispatch_request()
  File "/Users/wujialiang/Public/website/venv/lib/python3.7/site-packages/flask/app.py", line 1935, in dispatch_request
    return self.view_functions[rule.endpoint](**req.view_args)
  File "/Users/wujialiang/Public/website/venv/lib/python3.7/site-packages/flask_login/utils.py", line 261, in decorated_view
    return func(*args, **kwargs)
  File "/Users/wujialiang/Public/website/app/routes.py", line 101, in edit_profile
    return render_template("edit_profile.html",form=form)  # 这里是绑定模版 传参数
  File "/Users/wujialiang/Public/website/venv/lib/python3.7/site-packages/flask/templating.py", line 140, in render_template
    ctx.app,
  File "/Users/wujialiang/Public/website/venv/lib/python3.7/site-packages/flask/templating.py", line 120, in _render
    rv = template.render(context)
  File "/Users/wujialiang/Public/website/venv/lib/python3.7/site-packages/jinja2/environment.py", line 1090, in render
    self.environment.handle_exception()
  File "/Users/wujialiang/Public/website/venv/lib/python3.7/site-packages/jinja2/environment.py", line 832, in handle_exception
    reraise(*rewrite_traceback_stack(source=source))
  File "/Users/wujialiang/Public/website/venv/lib/python3.7/site-packages/jinja2/_compat.py", line 28, in reraise
    raise value.with_traceback(tb)
  File "/Users/wujialiang/Public/website/app/templates/edit_profile.html", line 1, in top-level template code
    {% extends "base.html" %}
  File "/Users/wujialiang/Public/website/app/templates/base.html", line 31, in top-level template code
    {% block content %} {% endblock %}
  File "/Users/wujialiang/Public/website/app/templates/edit_profile.html", line 4, in block "content"
    {{ form.hidden_tag() }}
  File "/Users/wujialiang/Public/website/venv/lib/python3.7/site-packages/flask_wtf/form.py", line 135, in hidden_tag
    u'\n'.join(text_type(f) for f in hidden_fields(fields or self))
  File "/Users/wujialiang/Public/website/venv/lib/python3.7/site-packages/flask_wtf/form.py", line 135, in <genexpr>
    u'\n'.join(text_type(f) for f in hidden_fields(fields or self))
  File "/Users/wujialiang/Public/website/venv/lib/python3.7/site-packages/flask_wtf/form.py", line 125, in hidden_fields
    for f in fields:
  File "/Users/wujialiang/Public/website/venv/lib/python3.7/site-packages/wtforms/form.py", line 57, in __iter__
    return iter(itervalues(self._fields))
AttributeError: 'EditForm' object has no attribute '_fields'
2020-02-05 12:11:52,733 INFO Website Starts up in [__init__.py 29]
2020-02-05 12:12:47,636 INFO Website Starts up in [__init__.py 29]
